<?xml version="1.0" ?>

<robot name="aarm">

    <material name="gray">
        <color rgba="0.2 0.2 0.2 1" />
    </material>
    <material name="black">
        <color rgba="0 0 0 1" />
    </material>
    <material name="white">
        <color rgba="1 1 1 1" />
    </material>
    <material name="red">
        <color rgba="1 0 0 1" />
    </material>
    <material name="blue">
        <color rgba="0 0 1 1" />
    </material>
    <material name="wall">
        <color rgba="0 0 0 0.4" />
    </material>


    <link name="base_link">

        <visual>
            <geometry>
                <box size="1.54 0.76 0.03" />
            </geometry>
            <material name="gray" />
        </visual>

        <collision>
            <geometry>
                <box size="1.54 0.76 0.03" />
            </geometry>
        </collision>

        <inertial>
            <mass value="25" />
            <inertia ixx="0.0" iyy="0.0" izz="0.0" ixy="0.0" ixz="0.0" iyz="0.0" />
        </inertial>

    </link>
    <link name="Left_wall">

        <visual>
            <geometry>
                <box size="0.02 0.96 1" />
            </geometry>
            <material name="wall" />
            <origin rpy="0 0 0" xyz="0 -0.2 0" />
        </visual>

        <collision>
            <geometry>
                <box size="0.02 0.96 1" />
            </geometry>
            <origin rpy="0 0 0" xyz="0 -0.2 0" />
        </collision>

        <inertial>
            <mass value="100" />
            <inertia ixx="0.0" iyy="0.0" izz="0.0" ixy="0.0" ixz="0.0" iyz="0.0" />
        </inertial>

    </link>
    <link name="right_wall">

        <visual>
            <geometry>
                <box size="0.02 0.96 1" />
            </geometry>
            <material name="wall" />
            <origin rpy="0 0 0" xyz="0 -0.2 0" />
        </visual>

        <collision>
            <geometry>
                <box size="0.02 0.96 1" />
            </geometry>
            <origin rpy="0 0 0" xyz="0 -0.2 0" />
        </collision>

        <inertial>
            <mass value="100" />
            <inertia ixx="0.0" iyy="0.0" izz="0.0" ixy="0.0" ixz="0.0" iyz="0.0" />
        </inertial>

    </link>
    <link name="back_wall">

        <visual>
            <geometry>
                <box size="1.94 0.1 1" />
            </geometry>
            <material name="wall" />
        </visual>

        <collision>
            <geometry>
                <box size="1.94 0.1 1" />
            </geometry>
        </collision>

        <inertial>
            <mass value="100" />
            <inertia ixx="0.0" iyy="0.0" izz="0.0" ixy="0.0" ixz="0.0" iyz="0.0" />
        </inertial>

    </link>
    <link name="bim">

        <visual>
            <geometry>
                <box size="1.54 0.04 0.04" />
            </geometry>
            <material name="white" />
            <origin rpy="0 1.5708 0" xyz="0 0 -0.04" />
        </visual>

        <collision>
            <geometry>
                <box size="1.54 0.04 0.04" />
            </geometry>
            <origin rpy="0 1.5708 0" xyz="0 0 -0.04" />
        </collision>

        <inertial>
            <mass value="1" />
            <inertia ixx="0.0" iyy="0.0" izz="0.0" ixy="0.0" ixz="0.0" iyz="0.0" />
        </inertial>

    </link>
    <link name="scrow">

        <visual>
            <geometry>
                <cylinder length="1" radius="0.005" />
            </geometry>
            <material name="white" />
            <origin rpy="0 0 0" xyz="0 0 0" />
        </visual>

        <collision>
            <geometry>
                <cylinder length="1" radius="0.005" />
            </geometry>
            <origin rpy="0 0 0" xyz="0 0 0" />
        </collision>

        <inertial>
            <mass value="0.1" />
            <inertia ixx="0.0" iyy="0.0" izz="0.0" ixy="0.0" ixz="0.0" iyz="0.0" />
        </inertial>

    </link>
    <link name="Lplate">

        <visual>
            <geometry>
                <cylinder length="0.004" radius="0.035" />
            </geometry>
            <material name="white" />
            <origin rpy="0 0 0" xyz="0 0 0" />
        </visual>

        <collision>
            <geometry>
                <cylinder length="0.004" radius="0.035" />
            </geometry>
            <origin rpy="0 0 0" xyz="0 0 0" />
        </collision>

        <inertial>
            <mass value="0.05" />
            <inertia ixx="0.0" iyy="0.0" izz="0.0" ixy="0.0" ixz="0.0" iyz="0.0" />
        </inertial>

    </link>
    <link name="Rplate">
        <visual>
            <geometry>
                <cylinder length="0.004" radius="0.035" />
            </geometry>
            <material name="white" />
            <origin rpy="0 0 0" xyz="0 0 0" />
        </visual>
        <collision>
            <geometry>
                <cylinder length="0.004" radius="0.035" />
            </geometry>
            <origin rpy="0 0 0" xyz="0 0 0" />
        </collision>

        <inertial>
            <mass value="0.05" />
            <inertia ixx="0.0" iyy="0.0" izz="0.0" ixy="0.0" ixz="0.0" iyz="0.0" />
        </inertial>

    </link>
    <link name="motorCh2">
        <visual>
            <geometry>
                <cylinder length="0.1" radius="0.025" />
            </geometry>
            <material name="black" />
            <origin rpy="0 0 0" xyz="0 0 0" />
        </visual>
        <collision>
            <geometry>
                <cylinder length="0.1" radius="0.025" />
            </geometry>
            <origin rpy="0 0 0" xyz="0 0 0" />
        </collision>

        <inertial>
            <mass value="0.3" />
            <inertia ixx="0.0" iyy="0.0" izz="0.0" ixy="0.0" ixz="0.0" iyz="0.0" />
        </inertial>

    </link>
    <link name="platform">
        <visual>
            <geometry>
                <box size="0.12 0.1 0.08" />
            </geometry>
            <material name="white" />
            <origin rpy="0 0 0" xyz="-0.03 -0.05 0" />
        </visual>
        <collision>
            <geometry>
                <box size="0.12 0.1 0.08" />
            </geometry>
            <origin rpy="0 0 0" xyz="-0.03 -0.05 0" />
        </collision>

        <inertial>
            <mass value="0.5" />
            <inertia ixx="0.0" iyy="0.0" izz="0.0" ixy="0.0" ixz="0.0" iyz="0.0" />
        </inertial>

    </link>
    <link name="motorCh1">
        <visual>
            <geometry>
                <cylinder length="0.35" radius="0.035" />
            </geometry>
            <material name="black" />
            <origin rpy="0 0 0" xyz="0 0 0.15" />
        </visual>
        <collision>
            <geometry>
                <cylinder length="0.35" radius="0.035" />
            </geometry>
            <origin rpy="0 0 0" xyz="0 0 0.15" />
        </collision>

        <inertial>
            <mass value="1.0" />
            <inertia ixx="0.1" iyy="0.1" izz="0.1" ixy="0" ixz="0" iyz="0" />
        </inertial>

    </link>
    <link name="link1">
        <visual>
            <geometry>
                <cylinder length="0.51" radius="0.0125" />
            </geometry>
            <material name="red" />
            <origin rpy="0 1.5708 0" xyz="0.255 0 0" />
        </visual>
        <collision>
            <geometry>
                <cylinder length="0.51" radius="0.0125" />
            </geometry>
            <origin rpy="0 1.5708 0" xyz="0.255 0 0" />
        </collision>

        <inertial>
            <mass value="0.5" />
            <inertia ixx="0.1" iyy="0.1" izz="0.5" ixy="0" ixz="0" iyz="0" />
        </inertial>

    </link>
    <link name="motorCh0">
        <visual>
            <geometry>
                <box size="0.19 0.05 0.05" />
            </geometry>
            <material name="black" />
            <origin rpy="0 1.5708 0" xyz="0 0 0.0925" />
        </visual>
        <collision>
            <geometry>
                <box size="0.19 0.06 0.06" />
            </geometry>
            <origin rpy="0 1.5708 0" xyz="0 0 0.0925" />
        </collision>

        <inertial>
            <mass value="0.5" />
            <inertia ixx="0" iyy="0" izz="0.5" ixy="0" ixz="0" iyz="0" />
        </inertial>

    </link>
    <link name="link0">
        <visual>
            <geometry>
                <cylinder length="0.43" radius="0.01" />
            </geometry>
            <material name="red" />
            <origin rpy="0 1.5708 0" xyz="0.215 0 0" />
        </visual>
        <collision>
            <geometry>
                <cylinder length="0.43" radius="0.01" />
            </geometry>
            <origin rpy="0 1.5708 0" xyz="0.215 0 0" />
        </collision>

        <inertial>
            <mass value="0.1" />
            <inertia ixx="0" iyy="0" izz="0.1" ixy="0" ixz="0" iyz="0" />
        </inertial>

    </link>
    <link name="end_effector">
        <visual>
            <geometry>
                <cylinder length="0.05" radius="0.004" />
            </geometry>
            <material name="white" />
        </visual>
        <collision>
            <geometry>
                <cylinder length="0.05" radius="0.004" />
            </geometry>
        </collision>

        <inertial>
            <mass value="0.1" />
            <inertia ixx="0" iyy="0" izz="0" ixy="0" ixz="0" iyz="0" />
        </inertial>

    </link>

    <link name="world" />

    <joint name="base_link_to_world" type="fixed">
        <origin rpy="0 0 0" xyz="0 0 0" />
        <parent link="world" />
        <child link="base_link" />
    </joint>


    <link name="camera">
        <collision>
          <origin xyz="0 0 0" rpy="0 0 0"/>
          <geometry>
            <box size="0.1 0.05 0.05"/>
          </geometry>
        </collision>
    
        <visual>
          <origin xyz="0 0 0" rpy="0 0 0"/>
          <geometry>
            <box size="0.05 0.05 0.1"/>
          </geometry>
          <material name="white"/>
        </visual>
    
        <inertial>
            <mass value="0.3" />
            <origin xyz="0 0 0" rpy="0 0 0"/>
            <inertia ixx="1e-6" ixy="0" ixz="0" iyy="1e-6" iyz="0" izz="1e-6" />
        </inertial>
    </link>
    
      <joint name="camera_joint" type="fixed">
        <axis xyz="0 0 1" />
        <origin xyz="0 0 2.5" rpy="0 1.57 1.57"/>
        <parent link="world"/>
        <child link="camera"/>
      </joint>


    <joint name="base_link_to_bim" type="fixed">
        <parent link="base_link" />
        <child link="bim" />
        <origin rpy="1.5708 0 1.5708" xyz="0.04 -0.36 0.015" />
    </joint>
    <joint name="base_link_to_Left_wall" type="fixed">
        1.54 0.76
        <parent link="base_link" />
        <child link="Left_wall" />
        <origin rpy="0 0 0" xyz="-0.97 0.05 0" />
    </joint>
    <joint name="base_link_to_right_wall" type="fixed">
        <parent link="base_link" />
        <child link="right_wall" />
        <origin rpy="0 0 0" xyz="0.97 0.05 0" />
    </joint>
    <joint name="base_link_to_back_wall" type="fixed">
        <parent link="base_link" />
        <child link="back_wall" />
        <origin rpy="0 0 0" xyz="0 -0.58 0" />
    </joint>
    <joint name="bim_to_scrow" type="fixed">
        <parent link="bim" />
        <child link="scrow" />
        <origin rpy="0 0 0" xyz="-0.04 0 0" />
    </joint>
    <joint name="bim_to_Rplate" type="fixed">
        <parent link="bim" />
        <child link="Rplate" />
        <origin rpy="0 0 0" xyz="-0.04 0 0.51" />
    </joint>
    <joint name="bim_to_Lplate" type="fixed">
        <parent link="bim" />
        <child link="Lplate" />
        <origin rpy="0 0 0" xyz="-0.04 0 -0.51" />
    </joint>
    <joint name="Lplate_to_motorCh2" type="fixed">
        <parent link="Lplate" />
        <child link="motorCh2" />
        <origin rpy="0 0 0" xyz="0 0 -0.055" />
    </joint>
    <joint name="prismatic" type="prismatic">
        <axis xyz="0 0 1" />
        <parent link="scrow" />
        <child link="platform" />
        <origin rpy="0 0 0" xyz="0.04 0.08 0" />
        <limit effort="1000.0" lower="-0.45" upper="0.45" velocity="0.1" />
        <dynamics damping="50" friction="200" />
    </joint>
    <joint name="platform_to_motorCh1" type="fixed">
        <parent link="platform" />
        <child link="motorCh1" />
        <origin rpy="-1.5708 0 0" xyz="0 0.025 0" />
    </joint>
    <joint name="revolute" type="revolute">
        <axis xyz="0 0 1" />
        <origin rpy="0 0 0" xyz="0 0 0" />
        <parent link="motorCh1" />
        <child link="link1" />
        <limit effort="100.0" lower="-1.7453" upper="1.7453" velocity="1.0" />
        <dynamics damping="5" friction="1" />
    </joint>
    <joint name="link1_to_motorCh0" type="fixed">
        <parent link="link1" />
        <child link="motorCh0" />
        <origin rpy="0 0 0" xyz="0.51 0 -0.0175" />
    </joint>
    <joint name="continuous" type="continuous">
        <parent link="motorCh0" />
        <child link="link0" />
        <axis xyz="0 0 1" />
        <origin rpy="0 0 0" xyz="0 0 -0.002" />
        <limit effort="60.0" velocity="1.0" />
        <dynamics damping="2" friction="0.5" />
    </joint>
    <joint name="link0_to_end_effector" type="fixed">
        <parent link="link0" />
        <child link="end_effector" />
        <origin rpy="0 0 0" xyz="0.425 0 -0.025" />
    </joint>


    <transmission name="trans_prismatic">
        <type>transmission_interface/SimpleTransmission</type>
        <joint name="prismatic">
            <hardwareInterface>hardware_interface/EffortJointInterface</hardwareInterface>
        </joint>
        <actuator name="prismatic_motor">
            <hardwareInterface>hardware_interface/EffortJointInterface</hardwareInterface>
            <mechanicalReduction>1</mechanicalReduction>
        </actuator>
    </transmission>
    <transmission name="trans_revolute">
        <type>transmission_interface/SimpleTransmission</type>
        <joint name="revolute">
            <hardwareInterface>hardware_interface/EffortJointInterface</hardwareInterface>
        </joint>
        <actuator name="revolute_motor">
            <hardwareInterface>hardware_interface/EffortJointInterface</hardwareInterface>
            <mechanicalReduction>10</mechanicalReduction>
        </actuator>
    </transmission>
    <transmission name="trans_continuous">
        <type>transmission_interface/SimpleTransmission</type>
        <joint name="continuous">
            <hardwareInterface>hardware_interface/EffortJointInterface</hardwareInterface>
        </joint>
        <actuator name="continuous_motor">
            <hardwareInterface>hardware_interface/EffortJointInterface</hardwareInterface>
            <mechanicalReduction>8</mechanicalReduction>
        </actuator>
    </transmission>


    <gazebo>
        <plugin name="gazebo_ros_control" filename="libgazebo_ros_control.so">
            <robotNamespace>/aarm</robotNamespace>
            <robotSimType>gazebo_ros_control/DefaultRobotHWSim</robotSimType>
            <legacyModeNS>true</legacyModeNS>
        </plugin>
    </gazebo>
    <gazebo reference="base_link">
        <material>Gazebo/DarkGrey</material>
        <mu1>0.2</mu1>
        <mu2>0.2</mu2>
        <selfCollide>false</selfCollide>
    </gazebo>
    <gazebo reference="Left_wall">
        <material>Gazebo/BlackTransparent</material>
    </gazebo>
    <gazebo reference="right_wall">
        <material>Gazebo/BlackTransparent</material>
    </gazebo>
    <gazebo reference="back_wall">
        <material>Gazebo/BlackTransparent</material>
        <selfCollide>true</selfCollide>
    </gazebo>
    <gazebo reference="bim">
        <material>Gazebo/White</material>
    </gazebo>
    <gazebo reference="scrow">
        <material>Gazebo/White</material>
    </gazebo>
    <gazebo reference="Lplate">
        <material>Gazebo/White</material>
    </gazebo>
    <gazebo reference="Rplate">
        <material>Gazebo/White</material>
    </gazebo>
    <gazebo reference="motorCh2">
        <material>Gazebo/Black</material>
    </gazebo>
    <gazebo reference="platform">
        <material>Gazebo/White</material>
    </gazebo>
    <gazebo reference="motorCh1">
        <material>Gazebo/Black</material>
    </gazebo>
    <gazebo reference="link1">
        <sensor name='link1_contact' type='contact'>
            <contact>
              <collision>box_collision</collision>
            </contact>
        </sensor>
        <material>Gazebo/Red</material>
        <mu1>0.2</mu1>
        <mu2>0.2</mu2>
        <selfCollide>false</selfCollide>
    </gazebo>
    <gazebo reference="motorCh0">
        <sensor name='motorCh0_contact' type='contact'>
            <contact>
              <collision>box_collision</collision>
            </contact>
        </sensor>
        <material>Gazebo/Black</material>
        <mu1>0.2</mu1>
        <mu2>0.2</mu2>
    </gazebo>
    <gazebo reference="link0">
        <sensor name='link0_contact' type='contact'>
            <contact>
              <collision>box_collision</collision>
            </contact>
        </sensor>
        <material>Gazebo/Red</material>
        <mu1>0.2</mu1>
        <mu2>0.2</mu2>
        <selfCollide>false</selfCollide>
    </gazebo>
    <gazebo reference="end_effector">
        <sensor name='end_effector_contact' type='contact'>
            <always_on>true</always_on>
            <contact>
              <collision>aarm_collision</collision>
              <update_rate> 5 </update_rate>
            </contact>
        </sensor>
        <material>Gazebo/white</material>
        <mu1>0.2</mu1>
        <mu2>0.2</mu2>
        <selfCollide>false</selfCollide>
    </gazebo>

    <gazebo reference="camera">
        <material>Gazebo/white</material>
        <sensor type="camera" name="camera1">
          <update_rate>60.0</update_rate>
          <camera name="head">
            <horizontal_fov>1</horizontal_fov>
            <vertical_fov>1</vertical_fov>
            <image>
              <width>800</width>
              <height>500</height>
              <format>R8G8B8</format>
            </image>
            <clip>
              <near>0.02</near>
              <far>300</far>
            </clip>
          </camera>
          <plugin name="camera_controller" filename="libgazebo_ros_camera.so">
            <alwaysOn>true</alwaysOn>
            <updateRate>0.0</updateRate>
            <cameraName>aarm/camera1</cameraName>
            <imageTopicName>image_raw</imageTopicName>
            <cameraInfoTopicName>camera_info</cameraInfoTopicName>
            <frameName>camera</frameName>
            <hackBaseline>0.07</hackBaseline>
            <distortionK1>0.0</distortionK1>
            <distortionK2>0.0</distortionK2>
            <distortionK3>0.0</distortionK3>
            <distortionT1>0.0</distortionT1>
            <distortionT2>0.0</distortionT2>
          </plugin>
        </sensor>
      </gazebo>
</robot>
